<mujoco model="ur5gripper">
    <compiler angle="radian"
              inertiafromgeom="true"
              texturedir="textures/"
              meshdir="mesh/visual/"/>
    <option timestep="1e-2"
            iterations="30"
            tolerance="1e-10"
            impratio="20"/>
    <size njmax="600" nconmax="150" nstack="300000"/>

    <default>
        <site rgba="0.8 0.6 0.7 0.3" type="ellipsoid" group="3"/>
        <geom contype='1' conaffinity='1' condim='4'  margin="1e-3" solref=".01 1" solimp=".99 .99 .01" />
        <joint armature="0.01" damping=".1"/>
        <default class="UR5">
            <joint damping='65'/>
        </default>
        <default class="UR5e">
            <joint damping='45'/>
        </default>
        <default class="GRIPPER">
            <joint damping='15'/>
        </default>
    </default>

    <visual>
        <map fogstart="3" fogend="5" znear="0.05"/>
        <quality shadowsize="2048"/>
        <scale framelength="0.1"
               framewidth="0.005"
               contactwidth="0.1"
               contactheight="0.005"
               forcewidth="0.01"
               />
    </visual>

    <!--Assets-->
    <asset>
        <!--Meshes-->
        <mesh name="base"           file="base.stl"     />
        <mesh name="shoulder"       file="shoulder.stl" />
        <mesh name="upperarm"       file="upperarm.stl" />
        <mesh name="forearm"        file="forearm.stl"  />
        <mesh name="wrist1"         file="wrist1.stl"   />
        <mesh name="wrist2"         file="wrist2.stl"   />
        <mesh name="wrist3"         file="wrist3.stl"   />
        <mesh name="gripperpalm"    file="palm.STL"     />
        <mesh name="link_0"         file="link_0.STL"   />
        <mesh name="link_1"         file="link_1.STL"   />
        <mesh name="link_2"         file="link_2.STL"   />
        <mesh name="link_3"         file="link_3.STL"   />
        <!--Textures-->
        <texture name="ur5_tex"     type="2d"       builtin="flat" height="32" width="32" rgb1="0.45 0.45 0.45" />
        <texture name="gripper_tex" type="2d"       builtin="flat" height="32" width="32" rgb1="0.45 0.45 0.45" rgb2="0 0 0"/>
        <texture name="bench_tex"   type="2d"       builtin="flat" height="32" width="32" rgb1="0.7 0.7 0.7" />
        <texture name="sky_tex"     type="skybox"   builtin="gradient" width="100" height="100" rgb1="1 1 1" rgb2="0.3 0.3 0.8" />
        <texture name="texgeom"     type="cube"     builtin="flat" mark="cross" width="127" height="1278" rgb1="0.8 0.6 0.4" rgb2="0.8 0.6 0.4" markrgb="1 1 1" random="0.01" />
        <texture name="floor_tex"   type="2d"        builtin="checker" rgb1=".2 .3 .4" rgb2=".1 .2 .3" width="100" height="100" />
        <texture name="wood"        type="cube"     file="wood2.png"/>
        <texture name="metal"        type="cube"     file="metal2.png"/>
        <!--Materials-->
        <material name="ur5_mat"        texture="ur5_tex"   shininess="0.9" specular="0.75" reflectance="0.3"/>
        <material name="gripper_mat"    texture="gripper_tex"   shininess="0.9" specular="0.75" reflectance="0.4"/>
        <material name='floor_mat'      texture="floor_tex"  shininess="0.8" texrepeat="10 10" specular="0.7"  reflectance="0.5" />
        <material name='geom'           texture="texgeom"   texuniform="true" />
        <material name="bench_mat"      texture="metal"   shininess="0.1" specular="0.5" reflectance="0.2"/>
        <material name="tablecube"      texture="wood" rgba=".8 .8 .8 1"/>
    </asset>

    <!--Contacts-->
    <contact>
        <exclude body1="box_link" body2="base_link"/>
		<exclude body1="base_link" body2="shoulder_link"/>
		<exclude body1="shoulder_link" body2="upper_arm_link"/>
        <exclude body1="upper_arm_link" body2="forearm_link"/>
		<exclude body1="forearm_link" body2="wrist_1_link"/>
		<exclude body1="wrist_1_link" body2="wrist_2_link"/>
        <exclude body1="wrist_2_link" body2="wrist_3_link"/>
        <exclude body1="ee_link" body2="wrist_3_link"/>
        <exclude body1="ee_link" body2="gripperpalm"/>
        <exclude body1='gripperpalm' body2='wrist_3_link' />
        <exclude body1='gripperpalm' body2='wrist_2_link' />
        <exclude body1='gripperpalm' body2='wrist_1_link' />
        <exclude body1='gripperpalm' body2='forearm_link' />
        <exclude body1='gripperpalm' body2='upper_arm_link' />
        
    </contact>

    <!--MODEL DESCRIPTION-->
    <worldbody>
        <!--Lighting parameters-->
        <light name="light3" mode="targetbody" target="box_link" directional="true" pos="1 1 3" />

        <!--Floor Property-->
        <geom name='floor' material="floor_mat" pos='0 0 0' size='2.5 2.5 0.1'  type='plane' />

        <!--Robot UR5-->
        <body name="box_link" pos="0 0 0.435">
            <geom size=".3 .2 .435" type="box" material="bench_mat"/>
            <geom size=".29 .19 .03" pos ="0 0 0.4" type="box" material="bench_mat"/>
            <geom size=".29 .19 .03" pos ="0 0 -0.2" type="box" material="bench_mat"/>
            <geom size=".04 .04 .435" pos =".26 .16 0" type="box" material="bench_mat"/>
            <geom size=".04 .04 .435" pos ="-.26 .16 0" type="box" material="bench_mat"/>
            <geom size=".04 .04 .435" pos =".26 -.16 0" type="box" material="bench_mat"/>
            <geom size=".04 .04 .435" pos ="-.26 -.16 0" type="box" material="bench_mat"/>
            <inertial pos="0 0 0" mass="1000" diaginertia="0 0 0" />
            <body name="base_link" pos="0 0 0.435" >
                <!-- To validate mujoco XML with IK solver, uncomment this and run mujocoXML_ik_validation.py 
                <geom name='eelink1' pos='-0.81725 -0.40915 -0.005491' type='box' size='0.005 0.01 0.02' rgba='0 1 0 1' quat='0.70710678 0.70710678 0.         0. ' />
                <geom name='eelink2' pos='0.47861376 0.12039538 0.2169973' type='box' size='0.005 0.01 0.02' rgba='0 1 0 1' quat='-4.29355962e-04  7.21356638e-01 -6.92255947e-01  2.06427328e-02' />
                <geom name='eelink3' pos='-0.29619086 0.11280353 0.19410002' type='box' size='0.005 0.01 0.02' rgba='0 1 0 1' quat='-4.29355858e-04 -6.91948246e-01  7.21651811e-01 -2.06427321e-02' />  -->
                <inertial pos="0 0 0" quat="0.5 0.5 -0.5 0.5" mass="4" diaginertia="0.0072 0.00443333 0.00443333" />
                <geom type="mesh"  mesh="base" material="ur5_mat"/>
                <body name="shoulder_link" pos="0 0 0.089159" quat='0 0 0 1' >
                    <inertial pos="0 0 0" mass="3.7" diaginertia="0.0102675 0.0102675 0.00666" />
                    <joint name="shoulder_pan_joint" class="UR5" pos="0 0 0" axis="0 0 1" limited="true" range="-3.14159 3.14159" />
                    <geom type="mesh"  mesh="shoulder" material="ur5_mat"/>
                    <body name="upper_arm_link" pos="0 0.13585 0" quat="0.707107 0 0.707107 0">
                        <inertial pos="0 0 0.28" mass="8.393" diaginertia="0.226891 0.226891 0.0151074" />
                        <joint name="shoulder_lift_joint" class="UR5" pos="0 0 0" axis="0 1 0" limited="true" range="-3.14159 0" /> <!--Range= -3.14159 3.14159-->
                        <geom type="mesh"  mesh="upperarm" material="ur5_mat"/>
                        <body name="forearm_link" pos="0 -0.1197 0.425">
                            <inertial pos="0 0 0.25" mass="2.275" diaginertia="0.0494433 0.0494433 0.004095" />
                            <joint name="elbow_joint" class="UR5" pos="0 0 0" axis="0 1 0" limited="true" range="-3.14159 3.14159" />
                            <geom type="mesh"  mesh="forearm" material="ur5_mat"/>
                            <body name="wrist_1_link" pos="0 0 0.39225" quat="0.707107 0 0.707107 0">
                                <inertial pos="0 0 0" quat="0.5 0.5 -0.5 0.5" mass="1.219" diaginertia="0.21942 0.111173 0.111173" />
                                <joint name="wrist_1_joint" class="UR5e" pos="0 0 0" axis="0 1 0" limited="true" range="-3.14159 3.14159" />
                                <geom type="mesh"  mesh="wrist1" material="ur5_mat"/>
                                <body name="wrist_2_link" pos="0 0.093 0">
                                    <inertial pos="0 0 0" quat="0.5 0.5 -0.5 0.5" mass="1.219" diaginertia="0.21942 0.111173 0.111173" />
                                    <joint name="wrist_2_joint" class="UR5e" pos="0 0 0" axis="0 0 1" limited="true" range="-3.14159 3.14159" />
                                    <geom type="mesh"  mesh="wrist2" material="ur5_mat"/>
                                    <body name="wrist_3_link" pos="0 0 0.09465">
                                        <inertial pos="0 0 0" quat="0.5 0.5 -0.5 0.5" mass="0.1879" diaginertia="0.033822 0.0171365 0.0171365" />
                                        <joint name="wrist_3_joint" class="UR5e" pos="0 0 0" axis="0 1 0" limited="true" range="-3.14159 3.14159" />
                                        <geom type="mesh"  mesh="wrist3" material="ur5_mat"/>
                                        <body name="ee_link" pos="0 0.0823 0" quat="0.707107 0 0 0.707107">
                                            <inertial pos="-0.01 0 0" mass="0.001" diaginertia="1.66667e-08 1.66667e-08 1.66667e-08" />
                                            <geom size="0.005 0.005 0.005" pos="-0.01 0 0" type="box" rgba='1 0 0 1' />
                                        </body>
                                        <!-- GRIPPER -->
                                        <!-- <geom name='eePoint' pos='0 0.3 0' type='box' size='0.005 0.005 0.005' rgba='1 0 0 1' /> -->
                                        <body name='gripperpalm' pos='0 0.11 0' quat='0 0 1 0' >
                                            <geom pos='0 0 0' type='capsule' size='0.05 0.03' quat='0.7071068 0 0.7071068 0' condim='3' density='100' />
                                            <geom pos='0 0 0.05' type='box' size='0.01 0.01 0.05' condim='3' />
                                            <body name='camera' pos='0 0 0.12' euler="20 0 0" >
                                                <geom pos='0 0 0' type='box' size='0.08 0.02 0.02' />
                                                <camera name='c1' euler="0 0 0" fovy="90" pos="0 .01 .01">
                                                </camera>
                                            </body>

                                            <body name='left_finger' pos='-0.06 0.05 0' quat='1 0 0 0'>
                                                <joint name='l_f' type='slide' pos='0 0 0' axis='1 0 0' range='0 0.05' damping='.1' limited='true'/>
                                                <geom pos='0 0.05 0' type='box' size='0.007 0.05 0.007' condim='6' friction='1 0.02 0.0005' />
                                                <body name='left_fingertip' pos='0 0.14 0' quat='0.7071068 0 0.7071068 0'>
                                                    <geom pos='0 0 0' type='cylinder' size='0.04 0.01' condim='6' density='1' friction='1 0.04 0.001' solref='1e-4 1' />
                                                    <site pos='0 0 0' type='cylinder' size='0.041 0.011' name='leftFingerMainTouch' />
                                                </body>
                                            </body>

                                            <body name='right_finger' pos='0.06 0.05 0' quat='1 0 0 0'>
                                                <joint name='r_f' type='slide' pos='0 0 0' axis='-1 0 0' range='0 0.05' damping='.1' limited='true'/>
                                                <geom pos='0 0.05 0' type='box' size='0.007 0.05 0.007' condim='6' friction='1 0.02 0.0005' />
                                                <body name='right_fingertip' pos='0 0.14 0' quat='-0.7071068 0 0.7071068 0'>
                                                    <geom pos='0 0 0' type='cylinder' size='0.04 0.01' condim='6' density='1' friction='1 0.04 0.001' solref='1e-4 1' />
                                                    <site pos='0 0 0' type='cylinder' size='0.041 0.011' name='rightFingerMainTouch' />
                                                </body>
                                            </body>
                                        </body>
                                    </body>
                                </body>
                            </body>
                        </body>
                    </body>
                </body>
                <body name="base" pos="0 0 0" quat="1.7949e-09 0 0 -1">
                    <inertial pos="0 0 0" quat="1.7949e-09 0 0 -1" mass="0" diaginertia="0 0 0" />
                </body>
            </body>
        </body>

        <body name='table' pos='0.402 0.2264 1.06' >
            <geom type='box' size='0.02 0.02 0.01' />
        </body>
        <body name='target' pos='0.402 0.2264 1.10' >
            <joint type='free' />
            <geom type='box' size='0.03 0.03 0.03' density='5' rgba='1 0 0 1' solref='5e-4 1' condim='6' />
        </body>

    </worldbody>


    <!--ACTUATORS-->
    <actuator>
        <!--UR5-->
        <position name='shoulder_pan' ctrllimited="true" ctrlrange="-3.14159 3.14159" joint='shoulder_pan_joint' kp="500"/>
        <position name='shoulder_lift' ctrllimited="true" ctrlrange="-3.14159 3.14159" joint='shoulder_lift_joint' kp="500"/>
        <position name='forearm' ctrllimited="true" ctrlrange="-3.14159 3.14159" joint='elbow_joint' kp="500"/>
        <position name='wrist_1' ctrllimited="true" ctrlrange="-3.14159 3.14159" joint='wrist_1_joint' kp="100"/>
        <position name='wrist_2' ctrllimited="true" ctrlrange="-3.14159 3.14159" joint='wrist_2_joint' kp="100"/>
        <position name='wrist_3' ctrllimited="true" ctrlrange="-3.14159 3.14159" joint='wrist_3_joint' kp="100"/>
        

<!--         <motor name='shoulder_pan_T' ctrllimited="true" ctrlrange="-2 2" joint='shoulder_pan_joint' gear="101"/> 
        <motor name='shoulder_lift_T' ctrllimited="true" ctrlrange="-2 2" joint='shoulder_lift_joint' gear="101"/>
        <motor name='forearm_T' ctrllimited="true" ctrlrange="-2 2" joint='elbow_joint' gear="101" />
        <motor name='wrist_1_T' ctrllimited="true" ctrlrange="-1 1" joint='wrist_1_joint' gear="101"/>  
        <motor name='wrist_2_T' ctrllimited="true" ctrlrange="-1 1" joint='wrist_2_joint' gear="101"/>
        <motor name='wrist_3_T' ctrllimited="true" ctrlrange="-1 1" joint='wrist_3_joint' gear="101"/>
        <motor name='gripper' ctrllimited='true' ctrlrange='-1 1' joint='l_f' gear='50'/>
 -->
        <velocity name='shoulder_pan_v' class="UR5" joint='shoulder_pan_joint' kv="10"/>
        <velocity name='shoulder_lift_v' class="UR5" joint='shoulder_lift_joint' />
        <velocity name='forearm_v' class="UR5" joint='elbow_joint' />
        <velocity name='wrist_1_v' class="UR5" joint='wrist_1_joint' />
        <velocity name='wrist_2_v' class="UR5" joint='wrist_2_joint'/>
        <velocity name='wrist_3_v' class="UR5" joint='wrist_3_joint'/>
        <!--Gripper-->
        <position name='gripper' joint="l_f" />
        <velocity name='gripper_v' class="GRIPPER" joint='l_f' />
    </actuator>

    <equality>
        <joint name='fingers' joint1="r_f" joint2="l_f" polycoef='0 1 0 0 0' />
    </equality>

    <sensor>
        <touch name='lf_main' site='leftFingerMainTouch' />
        <touch name='rf_main' site='rightFingerMainTouch' />
    </sensor>
</mujoco>
